Workbook

Sheet BÚSQUEDA
A2: BUSQUEDA 🔎 | B2: 545688
A4: ACTIVO FIJO | B4: {=IFERROR(_xlfn.XLOOKUP(TRIM(B2&""), TRIM(Monitores[ACTIVO FIJO]&""), Monitores[ACTIVO FIJO]),"")} -> 545688
A5: EQUIPO | B5: {=IFERROR(_xlfn.XLOOKUP(TRIM(B2&""), TRIM(Monitores[ACTIVO FIJO]&""), Monitores[EQUIPO]),"")} -> MONITOR DE SIGNOS VITALES
A6: MARCA | B6: {=IFERROR(_xlfn.XLOOKUP(TRIM(B2&""), TRIM(Monitores[ACTIVO FIJO]&""), Monitores[MARCA]),"")} -> EDAN
A7: MODELO | B7: {=IFERROR(_xlfn.XLOOKUP(TRIM(B2&""), TRIM(Monitores[ACTIVO FIJO]&""), Monitores[MODELO]),"")} -> M50
A8: SERIE | B8: {=IFERROR(_xlfn.XLOOKUP(TRIM(B2&""), TRIM(Monitores[ACTIVO FIJO]&""), Monitores[SERIE]),"")} -> 333123-M14102120037
A9: UBICACIÓN | B9: {=IFERROR(_xlfn.XLOOKUP(TRIM(B2&""), TRIM(Monitores[ACTIVO FIJO]&""), Monitores[SERVICIO]),"")} -> URGENCIAS

Sheet MONITORES
A1: ACTIVO FIJO | B1: EQUIPO | C1: MARCA | D1: MODELO | E1: SERIE | F1: SERVICIO
A2: 550514 | B2: MONITOR DE GASES | C2: DRAEGER | D2: VAMOS 2 | E2: ASAD-0021 | F2: BLOQUE QUIRÚRGICO
A3: 549358 | B3: MONITOR DE GASES | C3: DRAEGER | D3: SCIO | E3: ASHD-0001 | F3: BLOQUE QUIRÚRGICO
A4: 549360 | B4: MONITOR DE GASES | C4: DRAEGER | D4: SCIO | E4: ASFK-0085 | F4: BLOQUE QUIRÚRGICO | I4: BUSQUEDA | J4: 571126
A5: 569821 | B5: MONITOR DE GASES | C5: DRAEGER | D5: VAMOS | E5: ARXA-0026 | F5: BLOQUE QUIRÚRGICO
A6: 550483 | B6: MONITOR DE GASES | C6: DRAEGER | D6: VAMOS 2 | E6: ASAD-0022 | F6: BLOQUE QUIRÚRGICO | I6: ACTIVO FIJO | J6: =_xlfn.XLOOKUP(J4&"",Monitores[ACTIVO FIJO],Monitores[ACTIVO FIJO],TRUE) -> 571126
A7: 571126 | B7: MONITOR DE SIGNOS VITALES | C7: MINDAY | D7: uMEC 10 | E7: KN-45223120 | F7: HOSPITALIZACIÓN PEDIATRÍA (Ruta Dorada) | J7: =_xlfn.XLOOKUP(J4&"",Monitores[ACTIVO FIJO],Monitores[EQUIPO],TRUE) -> MONITOR DE SIGNOS VITALES
A8: 572718 | B8: SIISTEMA DE TELEVISION PARA MONITOREO DE PACIENTES | C8: PHILIPS | D8: EFFICIA CMS200 | E8: CN52101811 | F8: CUIDADO INTERMEDIO PEDIÁTRICO | J8: =_xlfn.XLOOKUP(J4&"",Monitores[ACTIVO FIJO],Monitores[MARCA],TRUE) -> MINDAY
A9: 545713 | B9: SIISTEMA DE TELEVISION PARA MONITOREO DE PACIENTES | C9: NIHON KOHDEN | D9: CNS 9601 | E9: 00741 | F9: CUIDADO INTERMEDIO ADULTO | J9: =_xlfn.XLOOKUP(J4&"",Monitores[ACTIVO FIJO],Monitores[MODELO],TRUE) -> uMEC 10
A10: 545718 | B10: SIISTEMA DE TELEVISION PARA MONITOREO DE PACIENTES | C10: NIHON KOHDEN | D10: CNS 9601 | E10: 00800 | F10: CUIDADO INTERMEDIO ADULTO | J10: =_xlfn.XLOOKUP(J4&"",Monitores[ACTIVO FIJO],Monitores[SERIE],TRUE) -> KN-45223120
A11: 545711 | B11: SIISTEMA DE TELEVISION PARA MONITOREO DE PACIENTES | C11: MINDRAY | D11: HIPERVISOR VI | E11: MXL3370766 | F11: CUIDADO INTENSIVO ADULTO | J11: =_xlfn.XLOOKUP(J4&"",Monitores[ACTIVO FIJO],Monitores[SERVICIO],TRUE) -> HOSPITALIZACIÓN PEDIATRÍA (Ruta Dorada)
A12: 545712 | B12: SIISTEMA DE TELEVISION PARA MONITOREO DE PACIENTES | C12: MINDRAY | D12: HIPERVISOR VI | E12: MXL3382XCC | F12: CUIDADO INTENSIVO ADULTO
A13: 547476 | B13: SIISTEMA DE TELEVISION PARA MONITOREO DE PACIENTES | C13: PHILIPS | D13: NO DEFINIDO | E13: 2UA3020MZ | F13: UNIDAD CRÍTICA OBSTÉTRICA
A14: 574122 | B14: SIISTEMA DE TELEVISION PARA MONITOREO DE PACIENTES | C14: MINDRAY | D14: CMS Benevision | E14: JB-97006131 | F14: UNIDAD CRÍTICA OBSTÉTRICA
A15: COMODATO 000900 | B15: MONITOR DE SIGNOS VITALES | C15: EDAN | D15: M50 | E15: 333123-M13A01810036 | F15: GASTROENTEROLOGÍA
A16: 549313 | B16: MONITOR DE SIGNOS VITALES | C16: EDAN | D16: M50 | E16: 33123-M15907420043-01 | F16: BLOQUE QUIRÚRGICO
A17: 545103 | B17: MONITOR DE SIGNOS VITALES | C17: MINDRAY | D17: MEC-1200 | E17: CC-32125139 | F17: BLOQUE QUIRÚRGICO
A18: 541627 | B18: MONITOR DE SIGNOS VITALES | C18: PENLON | D18: PM 8000 EXPRESS | E18: AA68C22551 | F18: BLOQUE QUIRÚRGICO
A19: 541211 | B19: MONITOR DE SIGNOS VITALES | C19: MINDRAY | D19: PM-9000 | E19: W-78101038 | F19: BLOQUE QUIRÚRGICO
A20: 541268 | B20: MONITOR DE SIGNOS VITALES | C20: MINDRAY | D20: PM-9000 | E20: W78101021 | F20: BLOQUE QUIRÚRGICO
A21: 545093 | B21: MONITOR DE SIGNOS VITALES | C21: MINDRAY | D21: MEC-1200 | E21: CC-32125137 | F21: BLOQUE QUIRÚRGICO
A22: 573303 | B22: MONITOR DE SIGNOS VITALES | C22: COMEN | D22: STAR 8000E | E22: E7200519036 | F22: CARDIOLOGÍA
A23: 545376 | B23: MONITOR DE SIGNOS VITALES | C23: EDAN | D23: M50 | E23: 333123-M13707020027-01 | F23: HOSPITALIZACIÓN GINECO-OBSTETRICIA
A24: 542143 | B24: MONITOR DE SIGNOS VITALES | C24: NIHON KOHDEN | D24: OPV-1500K | E24: 04056 | F24: HOSPITALIZACIÓN GINECO-OBSTETRICIA
A25: 545097 | B25: MONITOR DE SIGNOS VITALES | C25: MINDRAY | D25: MEC-1200 | E25: CC-32125152 | F25: HOSPITALIZACIÓN GINECO-OBSTETRICIA
A26: 545375 | B26: MONITOR DE SIGNOS VITALES | C26: EDAN | D26: M50 | E26: 333123-M13707020030-01 | F26: HOSPITALIZACIÓN GINECO-OBSTETRICIA
A27: 545695 | B27: MONITOR DE SIGNOS VITALES | C27: EDAN | D27: M50 | E27: 333123-M14102120051 | F27: HOSPITALIZACIÓN GINECO-OBSTETRICIA
A28: 545696 | B28: MONITOR DE SIGNOS VITALES | C28: EDAN | D28: M50 | E28: 333123-M14102120009 | F28: HOSPITALIZACIÓN GINECO-OBSTETRICIA
A29: 545094 | B29: MONITOR DE SIGNOS VITALES | C29: MINDRAY | D29: MEC-1200 | E29: CC-32125138 | F29: BLOQUE QUIRÚRGICO
A30: 545099 | B30: MONITOR DE SIGNOS VITALES | C30: MINDRAY | D30: MEC-1200 | E30: CC-32125144 | F30: BLOQUE QUIRÚRGICO
A31: 545100 | B31: MONITOR DE SIGNOS VITALES | C31: MINDRAY | D31: MEC-1200 | E31: CC-32125140 | F31: BLOQUE QUIRÚRGICO
A32: 545101 | B32: MONITOR DE SIGNOS VITALES | C32: MINDRAY | D32: MEC-1200 | E32: CC-32125141 | F32: BLOQUE QUIRÚRGICO
A33: 545104 | B33: MONITOR DE SIGNOS VITALES | C33: MINDRAY | D33: MEC-1200 | E33: CC-32125142 | F33: BLOQUE QUIRÚRGICO
A34: 545105 | B34: MONITOR DE SIGNOS VITALES | C34: MINDRAY | D34: MEC-1200 | E34: CC-32125147 | F34: BLOQUE QUIRÚRGICO
A35: 545106 | B35: MONITOR DE SIGNOS VITALES | C35: MINDRAY | D35: MEC-1200 | E35: CC-32125145 | F35: BLOQUE QUIRÚRGICO
A36: 549963 | B36: MONITOR DE SIGNOS VITALES | C36: EDAN | D36: IM8 | E36: 360001/M19910220036 | F36: HOSPITALIZACIÓN ADULTOS EXPANSIÓN
A37: 549962 | B37: MONITOR DE SIGNOS VITALES | C37: EDAN | D37: IM8 | E37: 360001/M19910220002 | F37: HOSPITALIZACIÓN ADULTOS EXPANSIÓN
A38: 540494 | B38: MONITOR DE SIGNOS VITALES | C38: MINDRAY | D38: PM 8000 EXPRESS | E38: AA-77101320 | F38: CUIDADO INTENSIVO NEONATAL
A39: 544587 | B39: MONITOR DE SIGNOS VITALES | C39: EDAN | D39: M8 | E39: 301204-K12100120009 | F39: CUIDADO INTENSIVO NEONATAL
A40: 544588 | B40: MONITOR DE SIGNOS VITALES | C40: EDAN | D40: M8 | E40: 301204-K12100120017 | F40: CUIDADO INTENSIVO NEONATAL
...

Sheet FORMATO
E1: EMPRESA SOCIAL DEL ESTADO HOSPITAL UNIVERSITARIO SAN JORGE DE PEREIRA | T1: CÓDIGO: GRF3MAN-FR35 VERSIÓN: 4.0 FECHA: 03-02-2025 PÁGINA: 1 DE 2
E3: LISTA DE CHEQUEO MANTENIMIENTO PREVENTIVO MONITORES DE SIGNOS VITALES, PULSOXIMETROS Y ELECTROCARDIOGRAFOS
B6: EQUIPO | E6: =BÚSQUEDA!B5 -> MONITOR DE SIGNOS VITALES | N6: MARCA | S6: =BÚSQUEDA!B6 -> EDAN
B7: MODELO | E7: =BÚSQUEDA!B7 -> M50 | N7: SERIE | S7: =BÚSQUEDA!B8 -> 333123-M14102120037
B8: ACTIVO FIJO | E8: =BÚSQUEDA!B4 -> 545688 | N8: UBICACIÓN | S8: =BÚSQUEDA!B9 -> URGENCIAS
B10: ACTIVIDADES REALIZADAS | T10: FECHA
T13: C | V13: NC | X13: NA
B14: INSPECCIÓN FÍSICA | E14: Asegúrese de que el equipo se enuentre limpio, sin humedad, sin objetos extraños y carcasa en buen estado.
E15: Verifique que los rotulos y etiquetas se encuentren en buen estado y legibles.
E16: Limpieza del equipo
B17: ALIMENTACIÓN | E17: Cable AC
E18: Enchufe/ receptáculo
E19: Contacto entre la toma de entrada del instrumento y el conector del cable de conexión
E20: Interruptores / Swiches
E21: Protecciones / Fusibles
E22: Estado y funcionamiento de la batería
B23: FUNCIONAMIENTO | E23: Autocomprobación de encendido
E24: Fecha y hora correctas
E25: Verificacion de estado de los modulos multiparametros CO, BIS, PICCO (Anclaje, pilotos, contactos y conectores)
E26: Estado y funcionamiento de ECG (Cable troncal, latiguillos)
E27: Estado y funcionamiento de GA
E28: Estado y funcionamiento de ICG
E29: Estado y funcionamiento de CO2
E30: Estado y funcionamiento de RM (Mecanica respiratoria)
E31: Estado y funcionamiento de NIBP (Manguera, brazalete, conectores, acoples y fugas)
E32: Estado y funcionamiento de SPO2 (Sensor y extensión)
E33: Calibracion de parametros desde el menu según corresponda
E34: Estado y funcionamiento de IBP (Cable)
E35: Estado y funcionamiento de la temperaura (Sensor )
E36: Funcionamiento de la impresora
B37: PANTALLA | E37: Estado de la pantalla y touch screen del equipo
E38: Calibracion de touchscreen
E39: Configuracion de brillo
E40: Configuración de control de visualización
B41: ALARMAS | E41: Indicadores luminosos
E42: Señales audibles
E44: EMPRESA SOCIAL DEL ESTADO HOSPITAL UNIVERSITARIO SAN JORGE DE PEREIRA | T44: CÓDIGO: GRF3MAN-FR35 VERSIÓN: 4.0 FECHA: 03-02-2025 PÁGINA: 2 DE 2
E46: LISTA DE CHEQUEO MANTENIMIENTO PREVENTIVO MONITORES DE SIGNOS VITALES, PULSOXIMETROS Y ELECTROCARDIOGRAFOS
B49: EQUIPO | E49: =BÚSQUEDA!B5 -> MONITOR DE SIGNOS VITALES | N49: MARCA | S49: =BÚSQUEDA!B6 -> EDAN
B50: MODELO | E50: =BÚSQUEDA!B7 -> M50 | N50: SERIE | S50: =BÚSQUEDA!B8 -> 333123-M14102120037
...
