Workbook
Name CAUSA: GENERALIDADES!$B$2:$B$6
Name ESTADO: GENERALIDADES!$C$2:$C$3
Name PARADA: GENERALIDADES!$I$2:$I$3
Name RONDAS: GENERALIDADES!$E$2:$E$6
Name TIPO_REPORTE: GENERALIDADES!$A$2
Name TIPODEPARADA: GENERALIDADES!$J:$J

Sheet GENERALIDADES
A1: ORIGEN REPORTE | B1: CAUSA | C1: ESTADO | D1: OPORTUNIDAD (<3 DIAS HABILES) | E1: RONDAS | F1: UBICACION | G1: SERVICIO | H1: EQUIPOS | I1: PARADA | J1: TIPO DE PARADA | K1: PARADA DEL SERVICIO | L1: EQUIPO DE CONTINGENCIA | M1: EJECUTADO POR | N1: ESTADO GMA | O1: ESTADO DEL EQUIPO | P1: ACCESORIOS NUEVOS?
A2: GMA | B2: USO INADECUADO | C2: EN PROCESO | D2: 3 | E2: NO FUNCIONAL | F2: CONSULTORIO ODONTOLÓGICO | G2: ALMACÉN | H2: AUTOCLAVE | I2: SI | J2: TOTAL | K2: SI | L2: SI | M2: Victor Lopez | N2: 📑 SOLICITADO | O2: 🟢 FUNCIONAL | P2: SÍ
A3: RONDAS DE SEGURIDAD | B3: FALTA DE CONSUMIBLE | C3: CERRADO | E3: NO EXISTE | F3: CONSULTORIO MÉDICO | G3: BANCO DE SANGRE | H3: TENSIÓMETRO DE PARED | I3: NO | J3: N/A | K3: NO | L3: N/A | M3: Cristian Hurtado | N3: ⌛ PTE DE RESPUESTA | O3: 🟡 EN ESPERA DE REPUESTO | P3: NO
B4: INADECUADA CONFIGURACIÓN | C4: EN ESPERA DE REPUESTO | F4: ENFERMERÍA | G4: BLOQUE QUIRÚRGICO | H4: UNIDAD ODONTOLÓGICA | J4: PARCIAL | L4: NO | M4: Camilo Ramirez | N4: ❌ NO ACEPTADO | O4: 🔴 FUERA DE SERVICIO
B5: DESGASTE | C5: PENDIENTE COTIZAR | F5: OBSERVACION | G5: CARDIOLOGÍA | H5: REGULADOR DE OXÍGENO | M5: Tatiana Salazar | N5: ⚙ TRABAJANDO
B6: FALLA INTERNA | C6: PENDIENTE VISITA PROVEEDOR | F6: PROCEDIMIENTOS | G6: CENTRAL DE AIRE MEDICINAL | H6: OXIMETRO DE PULSO | M6: Leonardo Marín | N6: 📖 LEÍDO
B7: FACTOR EXTERNO | C7: PENDIENTE | F7: REANIMACION | G7: CENTRAL DE ESTERILIZACIÓN | H7: MONITOR DE SIGNOS VITALES | M7: David Ospina | N7: 🤝 CONFIRMADO
B8: ANTIGUEDAD DE CONSUMIBLE | C8: TRASLADADO | F8: CONSULTORIO 1 | G8: CONSULTA EXTERNA | H8: EQUIPO DE ÓRGANOS PORTATIL | N8: ⚠ PTE POR CONFIRMAR
B9: DEFECTOS DE FABRICA | F9: CONSULTORIO 2 | G9: HOSPITALIZACIÓN ADULTOS EXPANSIÓN 2° PISO | H9: EQUIPO DE ÓRGANOS DE PARED | N9: 🔄 TRANSFERIDO
B10: CONDICIONES DE INFRAESTRUCTURA | F10: CONSULTORIO 3 | G10: HOSPITALIZACIÓN ADULTOS EXPANSIÓN 3° PISO | H10: COMPRESOR
B11: PÉRDIDA | F11: CONSULTORIO 4 | G11: FARMACIA | H11: ESCARIFICADOR DENTAL ULTRASONICO
B12: USO EXCESIVO | F12: CONSULTORIO 5 | G12: GASTROENTEROLOGÍA | H12: BÁSCULA PEDIÁTRICA
B13: ANTIGUEDAD DEL EQUIPO | F13: CONSULTORIO 6 | G13: HOSPITALIZACIÓN GINECO-OBSTETRICIA | H13: BÁSCULA DE PISO
B14: FALTA DE MANTENIMIENTO | F14: CONSULTORIO 7 | G14: HOSPITALIZACIÓN PEDIATRÍA (Ruta Dorada) | H14: TENSIÓMETRO MANUAL
B15: TIEMPO DE VIDA ÚTIL | F15: CONSULTORIO 8 | G15: HEMODIÁLISIS | H15: GLUCÓMETRO
B16: DESCONOCIMIENTO DEL EQUIPO | F16: CONSULTORIO 9 | G16: HOSPITALIZACIÓN PEDIATRÍA | H16: BOMBA DE INFUSIÓN
B17: NO PRESENTA DAÑO | F17: CONSULTORIO 10 | G17: HOSPITALIZACIÓN ADULTO 5° PISO | H17: INCUBADORA
B18: DESAJUSTE | G18: IMÁGENES DIAGNÓSTICAS | H18: NEVERA
G19: CUIDADO INTERMEDIO ADULTO | H19: VACUTRON
G20: CUIDADO INTERMEDIO PEDIÁTRICO | H20: CAMA ELÉCTRICA
G21: INVENTARIOS | H21: FLUJÓMETRO
G22: LABORATORIO CLÍNICO | H22: PESA BEBÉ/BALANZA PEDIÁTRICA
G23: MANTENIMIENTO BIOMÉDICO | H23: FONENDOSCOPIO
G24: HOSPITALIZACIÓN ADULTO 4° PISO | H24: FRONTOLUZ
G25: ONCOLOGÍA | H25: LARINGOSCOPIO
G26: PATOLOGÍA | H26: BÁSCULA/PESA
G27: CUIDADO INTERMEDIO NEONATAL | H27: MESA DE CIRUGÍA
G28: PEDIATRÍA EXPANSIÓN | H28: ESPIRÓMETRO
G29: QUIMIOTERAPIA | H29: CALENTADOR DE GEL
G30: QUIRÓFANO | H30: MONITOR FETAL
... G40: LABORATORIO PATOLOGÍA | H40: DESFIBRILADOR
H41: ESTERILIZADOR / AUTOCLAVE
H42: TENSIÓMETRO DIGITAL
H43: INFUSOR
H44: CENTRAL DE MONITOREO
H45: ESTIMULADOR DE NERVIO PERIFÉRICO
H46: MICROSCOPIO
H47: BOMBA DE NUTRICIÓN
H48: CENTRÍFUGA
H49: LÁMPARA DE FOTOTERAPIA
...

Sheet MARZO
A1: No. REPORTE | B1: FECHA CREACIÓN DE SOLICITUD | C1: EQUIPO | D1: MARCA | E1: MODELO | F1: SERIE | G1: ACTIVO FIJO | H1: SERVICIO | I1: UBICACIÓN | J1: DESCRIPCIÓN DE DAÑO | K1: ACCIÓN REALIZADA | L1: EJECUTADO POR | M1: FECHA DE ATENCIÓN A LA SOLICITUD | N1: ESTADO EN GMA SOPORTE | O1: ESTADO DEL EQUIPO | P1: OPORTUNIDAD | Q1: FECHA DE CIERRE A LA SOLICITUD | R1: TIEMPO DE CIERRE A LA SOLICITUD | S1: PARADA DEL EQUIPO | T1: TIPO DE PARADA | U1: TIEMPO DE PARADA DEL EQUIPO | V1: PARADA DEL SERVICIO | W1: EQUIPO DE CONTINGENCIA | X1: TIEMPO DE PARA DEL SERVICIO | Y1: CAUSA | Z1: ACCESORIO NUEVO? | AA1: OBSERVACIONES | AB1: COMENTARIOS ADICIONALES | AC1: ESTADO | AD1: Tiempo de Oportunidad (horas) | AE1: Tiempo de Parada(dias) | AF1: Capacidad_Respuesta (<3_DIA)
A2: 25655 | B2: 46082 | C2: DOPPLER FETAL | D2: N/A | E2: N/A | F2: N/A | G2: N/A | H2: HOSPITALIZACIÓN GINECO-OBSTETRICIA | I2: Sala de Partos | J2: se solicita revisar doppler fetal de sala de partos, no carga, gracias | K2: Se realiza revisión del equipo y se encuentra en buenas condiciones funcionales, se verifica estado del cargador y de las baterías y se hacen pruebas funcionales, se retorna al servicio en buenas condiciones. | L2: Victor Lopez | M2: 46082 | N2: ⚠ PTE POR CONFIRMAR | O2: 🟢 FUNCIONAL | P2: =M2-B2 -> 0 | Q2: 46082 | R2: =IF(Q2-B2<0,NOW()-B2,Q2-B2) -> 0 | S2: NO | T2: N/A | U2: =IF(R2=GENERALIDADES!$I$1,#REF!,"0") -> 0 | V2: NO | W2: N/A | X2: =IF(U2=GENERALIDADES!$K$3,T2,"0") -> 0 | Y2: DESAJUSTE | Z2: NO | AC2: CERRADO | AD2: =M2-B2 -> 0 | AE2: =NETWORKDAYS(B2,Q2,) -> 0 | AF2: =IF(AND((NETWORKDAYS(B2,M2,)<=3),(NOT(ISBLANK(B2)))),TRUE(), FALSE()) -> TRUE
A3: 25659 | B3: 46082 | C3: BOMBA DE INFUSIÓN | D3: N/A | E3: N/A | F3: N/A | G3: N/A | H3: HOSPITALIZACIÓN PEDIATRÍA | J3: se solicita revision de bomba de infusion ubicada en el cuarto de equipos de expansion pediatria ,gracias | K3: Se revisa equipo y se encuentra en buenas condiciones funcionales, se realiza pruebas con test y se verifican configuraciones y alarmas. | L3: Victor Lopez | M3: 46082 | N3: ⚠ PTE POR CONFIRMAR | O3: 🟢 FUNCIONAL | P3: =M3-B3 -> 0 | Q3: 46082 | R3: =IF(Q3-B3<0,NOW()-B3,Q3-B3) -> 0 | S3: NO | T3: N/A | U3: =IF(R3=GENERALIDADES!$I$1,#REF!,"0") -> 0 | V3: NO | W3: N/A | X3: =IF(U3=GENERALIDADES!$K$3,T3,"0") -> 0 | Y3: NO PRESENTA DAÑO | Z3: NO | AC3: CERRADO | AD3: =M3-B3 -> 0 | AE3: =NETWORKDAYS(B3,Q3,) -> 0 | AF3: =IF(AND((NETWORKDAYS(B3,M3,)<=3),(NOT(ISBLANK(B3)))),TRUE(), FALSE()) -> TRUE
A4: 25660 | B4: 46082 | C4: CAMA ELÉCTRICA | D4: Stryker | E4: SV2 | F4: 15731020290033 | G4: 571768 | H4: HOSPITALIZACIÓN ADULTO 5° PISO | J4: buenas tardes. se solicita por favor revisar cama que se encuentra en el pasillo del quinto piso ya que no funciona el boton para bajar la parte inferior (pies). | K4: Se revisa cama y se encuentra en buenas condiciones funcionales, tenía bloqueo mecánico de los pies, se hacen recomendaciones de uso al personal asistencial. Equipo Ok. | L4: Victor Lopez | M4: 46083 | N4: ⚠ PTE POR CONFIRMAR | O4: 🟢 FUNCIONAL | P4: =M4-B4 -> 1 | Q4: 46083 | R4: =IF(Q4-B4<0,NOW()-B4,Q4-B4) -> 1 | S4: NO | T4: N/A | U4: =IF(R4=GENERALIDADES!$I$1,#REF!,"0") -> 0 | V4: NO | W4: N/A | X4: =IF(U4=GENERALIDADES!$K$3,T4,"0") -> 0 | Y4: DESCONOCIMIENTO DEL EQUIPO | Z4: NO | AC4: CERRADO | AD4: =M4-B4 -> 1 | AE4: =NETWORKDAYS(B4,Q4,) -> 1 | AF4: =IF(AND((NETWORKDAYS(B4,M4,)<=3),(NOT(ISBLANK(B4)))),TRUE(), FALSE()) -> TRUE
A5: 25661 | B5: 46082 | C5: FLUJÓMETRO | D5: N/A | E5: N/A | F5: N/A | G5: N/A | H5: HOSPITALIZACIÓN PEDIATRÍA | J5: buena tarde. se solicita revicion de flujometro que se encuentra en el cuarto de equipos. gracias | K5: Se revisa equipo y se encuentra en buenas condiciones funcionales, se verifica que no haya fugas. Equipo Ok. | L5: Victor Lopez | M5: 46082 | N5: ⚠ PTE POR CONFIRMAR | O5: 🟢 FUNCIONAL | P5: =M5-B5 -> 0 | Q5: 46082 | R5: =IF(Q5-B5<0,NOW()-B5,Q5-B5) -> 0 | S5: NO | T5: N/A | U5: =IF(R5=GENERALIDADES!$I$1,#REF!,"0") -> 0 | V5: NO | W5: N/A | X5: =IF(U5=GENERALIDADES!$K$3,T5,"0") -> 0 | Y5: NO PRESENTA DAÑO | Z5: NO | AC5: CERRADO | AD5: =M5-B5 -> 0 | AE5: =NETWORKDAYS(B5,Q5,) -> 0 | AF5: =IF(AND((NETWORKDAYS(B5,M5,)<=3),(NOT(ISBLANK(B5)))),TRUE(), FALSE()) -> TRUE
A6: 25663 | B6: 46082 | C6: MONITOR DE SIGNOS VITALES | D6: N/A | E6: N/A | F6: N/A | G6: N/A | H6: HOSPITALIZACIÓN ADULTO 5° PISO | J6: se solicita por favor revisar pulxovimetro de asignacion 2-3 de quinto piso gracias | K6: Solicitud repetida, repuestos solicitados | L6: Victor Lopez | M6: 46082 | N6: ⚠ PTE POR CONFIRMAR | O6: 🟢 FUNCIONAL | P6: =M6-B6 -> 0 | Q6: 46082 | R6: =IF(Q6-B6<0,NOW()-B6,Q6-B6) -> 0 | S6: NO | T6: N/A | U6: =IF(R6=GENERALIDADES!$I$1,#REF!,"0") -> 0 | V6: NO | W6: N | X6: =IF(U6=GENERALIDADES!$K$3,T6,"0") -> 0 | Y6: FALTA DE CONSUMIBLE | Z6: NO | AC6: CERRADO | AD6: =M6-B6 -> 0 | AE6: =NETWORKDAYS(B6,Q6,) -> 0 | AF6: =IF(AND((NETWORKDAYS(B6,M6,)<=3),(NOT(ISBLANK(B6)))),TRUE(), FALSE()) -> TRUE
A7: 25676 | B7: 46083 | C7: MONITOR DE SIGNOS VITALES | D7: Edan | E7: M50 | F7: 333123-M13707020019-01 | G7: 545370 | H7: HOSPITALIZACIÓN ADULTO 4° PISO | J7: buenos dias, se solicita el favor de arreglo o cambio te tensiometro de la estacion 3 de medicina interna. | K7: Solicitud repetida, repuestos solicitados | L7: Victor Lopez | M7: 46083 | N7: ⚠ PTE POR CONFIRMAR | O7: 🟢 FUNCIONAL | P7: =M7-B7 -> 0 | Q7: 46082 | R7: =IF(Q7-B7<0,NOW()-B7,Q7-B7) -> 31.649708 | S7: NO | T7: N/A | U7: =IF(R7=GENERALIDADES!$I$1,#REF!,"0") -> 0 | V7: NO | W7: N | X7: =IF(U7=GENERALIDADES!$K$3,T7,"0") -> 0 | Y7: FALTA DE CONSUMIBLE | Z7: NO | AC7: CERRADO | AD7: =M7-B7 -> 0 | AE7: =NETWORKDAYS(B7,Q7,) -> -1 | AF7: =IF(AND((NETWORKDAYS(B7,M7,)<=3),(NOT(ISBLANK(B7)))),TRUE(), FALSE()) -> TRUE
A8: 25677 | B8: 46083 | C8: MONITOR DE SIGNOS VITALES | D8: Edan | E8: M50 | F8: 333123-M13707020019-01 | G8: 545370 | H8: HOSPITALIZACIÓN ADULTO 4° PISO | J8: buenos dias, se solicita el favor de arreglo o cambio te saturador de la estacion 3 de medicina interna. | K8: Se revisa monitor y se encuentra daño en sensor de SPO2, no permite reparación, requiere cambio, se inicia proceso de adquisición del repuesto. | L8: Victor Lopez | M8: 46083 | N8: ⚙ TRABAJANDO | O8: 🟡 EN ESPERA DE REPUESTO | P8: =M8-B8 -> 0 | Q8: 46083 | R8: =IF(Q8-B8<0,NOW()-B8,Q8-B8) -> 0 | S8: NO | T8: N/A | U8: =IF(R8=GENERALIDADES!$I$1,#REF!,"0") -> 0 | V8: NO | W8: N/A | X8: =IF(U8=GENERALIDADES!$K$3,T8,"0") -> 0 | Y8: FALTA DE CONSUMIBLE | Z8: NO | AC8: PENDIENTE | AD8: =M8-B8 -> 0 | AE8: =NETWORKDAYS(B8,Q8,) -> 1 | AF8: =IF(AND((NETWORKDAYS(B8,M8,)<=3),(NOT(ISBLANK(B8)))),TRUE(), FALSE()) -> TRUE
A9: 25680 | B9: 46083 | C9: VENTILADOR MECÁNICO | D9: N/A | E9: N/A | F9: N/A | G9: N/A | H9: CUIDADO INTENSIVO NEONATAL | J9: tapa protectora de la valvula exhalatoria del ventilador #3 reventada | K9: Se revisa válvula y se encuentra daño en tapa, se procede a realizar el cambio de la tapa y se hacen pruebas funcionales. | L9: Victor Lopez | M9: 46083 | N9: ⚠ PTE POR CONFIRMAR | O9: 🟢 FUNCIONAL | P9: =M9-B9 -> 0 | Q9: 46083 | R9: =IF(Q9-B9<0,NOW()-B9,Q9-B9) -> 0 | S9: NO | T9: N/A | U9: =IF(R9=GENERALIDADES!$I$1,#REF!,"0") -> 0 | V9: NO | W9: N/A | X9: =IF(U9=GENERALIDADES!$K$3,T9,"0") -> 0 | Y9: DESGASTE | Z9: NO | AC9: CERRADO | AD9: =M9-B9 -> 0 | AE9: =NETWORKDAYS(B9,Q9,) -> 1 | AF9: =IF(AND((NETWORKDAYS(B9,M9,)<=3),(NOT(ISBLANK(B9)))),TRUE(), FALSE()) -> TRUE
A10: 25688 | B10: 46083 | C10: REGULADOR DE OXÍGENO | D10: N/A | E10: N/A | F10: N/A | G10: N/A | H10: QUIRÓFANO | J10: buenos dias por fvaor revisar aire de pared sala 3 gracias | K10: Se revisa equipo y se encuentra desajuste en manguera y conector de aire, se procede a realizar el ajuste correspondiente y se hacen pruebas funcionales. | L10: Camilo Ramirez | M10: 46083 | N10: ⚠ PTE POR CONFIRMAR | O10: 🟢 FUNCIONAL | P10: =M10-B10 -> 0 | Q10: 46083 | R10: =IF(Q10-B10<0,NOW()-B10,Q10-B10) -> 0 | S10: NO | T10: N/A | U10: =IF(R10=GENERALIDADES!$I$1,#REF!,"0") -> 0 | V10: NO | W10: N/A | X10: =IF(U10=GENERALIDADES!$K$3,T10,"0") -> 0 | Y10: DESAJUSTE | Z10: NO | AC10: CERRADO | AD10: =M10-B10 -> 0 | AE10: =NETWORKDAYS(B10,Q10,) -> 1 | AF10: =IF(AND((NETWORKDAYS(B10,M10,)<=3),(NOT(ISBLANK(B10)))),TRUE(), FALSE()) -> TRUE
A11: 25702 | B11: 46083 | C11: DESFIBRILADOR | D11: Nihon Kohden | E11: TEC-5631 | F11: 01738 | G11: 574600 | H11: CUIDADO INTENSIVO PEDIÁTRICO | J11: buena tarde se solicita favor de revisar desfibrilador de la uci pediatrica ya que se estaba usando en codigo y empezo a sonar por bateria a los pocos minutos de desconectarlo | K11: Se revisa equipo y se haecen pruebas funcionales, el equipo funciona normalmente pero requiere cambio de baterías por cumplimiento de tiempo de vida útil, se inicia proceso de adquisición de repuesto. | L11: Victor Lopez | M11: 46083 | N11: ⚙ TRABAJANDO | O11: 🟡 EN ESPERA DE REPUESTO | P11: =M11-B11 -> 0 | Q11: 46083 | R11: =IF(Q11-B11<0,NOW()-B11,Q11-B11) -> 0 | S11: NO | T11: N/A | U11: =IF(R11=GENERALIDADES!$I$1,#REF!,"0") -> 0 | V11: NO | W11: N/A | X11: =IF(U11=GENERALIDADES!$K$3,T11,"0") -> 0 | Y11: DESGASTE | Z11: NO | AC11: PENDIENTE | AD11: =M11-B11 -> 0 | AE11: =NETWORKDAYS(B11,Q11,) -> 1 | AF11: =IF(AND((NETWORKDAYS(B11,M11,)<=3),(NOT(ISBLANK(B11)))),TRUE(), FALSE()) -> TRUE
A12: 25713 | B12: 46083 | C12: INCUBADORA | D12: Bng Medical | E12: EcoLa 3000 | F12: A0210518248N | G12: 572798 | H12: CUIDADO INTENSIVO NEONATAL | J12: buena tarde se solicita reparar incubadora marca bng con activo fijo numero 572798 ubicada en el cubiculo 11 de uci neonatos ya que muestra falla el sensor de temperatura y no calienta , gracia spro su pronta colaboracion , | K12: Se revisa el equipo y se enceuntra módulo de sensor de piel desconectado en la base, se procede a realizar el ajuste del conector y se hacen pruebas funcionales, se entrega al servicio en buenas condiciones. | L12: Victor Lopez | M12: 46084 | N12: ⚠ PTE POR CONFIRMAR | O12: 🟢 FUNCIONAL | P12: =M12-B12 -> 1 | Q12: 46084 | R12: =IF(Q12-B12<0,NOW()-B12,Q12-B12) -> 1 | S12: NO | T12: N/A | U12: =IF(R12=GENERALIDADES!$I$1,#REF!,"0") -> 0 | V12: NO | W12: N/A | X12: =IF(U12=GENERALIDADES!$K$3,T12,"0") -> 0 | Y12: DESAJUSTE | Z12: NO | AC12: CERRADO | AD12: =M12-B12 -> 1 | AE12: =NETWORKDAYS(B12,Q12,) -> 2 | AF12: =IF(AND((NETWORKDAYS(B12,M12,)<=3),(NOT(ISBLANK(B12)))),TRUE(), FALSE()) -> TRUE
A13: 25719 | B13: 46084 | C13: NEVERA | D13: Harris | E13: HLT23U4BBA12 | F13: T016D66907TD | G13: 505204 | H13: BANCO DE SANGRE | J13: hola, buen dia, se solicita amablemente la revision de la nevera numero 2 ya que esta presenta subidas de temperatura, se necesita refrigerante | K13: Se revisa equipo y se realiza procedimiento de nivelación de refrigerante, se realizan pruebas funcionales, equipo Ok | L13: David Ospina | M13: 46084 | N13: ⚠ PTE POR CONFIRMAR | O13: 🟢 FUNCIONAL | P13: =M13-B13 -> 0 | Q13: 46084 | R13: =IF(Q13-B13<0,NOW()-B13,Q13-B13) -> 0 | U13: =IF(R13=GENERALIDADES!$I$1,#REF!,"0") -> 0 | X13: =IF(U13=GENERALIDADES!$K$3,T13,"0") -> 0 | AD13: =M13-B13 -> 0 | AE13: =NETWORKDAYS(B13,Q13,) -> 1 | AF13: =IF(AND((NETWORKDAYS(B13,M13,)<=3),(NOT(ISBLANK(B13)))),TRUE(), FALSE()) -> TRUE
A14: 25720 | B14: 46084 | C14: MONITOR DE SIGNOS VITALES | D14: Edan | E14: M50 | F14: 333123-M14102120051 | G14: 545695 | H14: HOSPITALIZACIÓN GINECO-OBSTETRICIA | J14: por favor revisar saturador del monitor de signos de estacion 2 ginecologia | K14: Se revisa equipo y se encuentra daño en conector del sensor al equipo, se procede a reparar el sensor y se realizan pruebas funcionales, se entrega al servicio en buenas condiciones. | L14: Victor Lopez | M14: 46084 | N14: ⚠ PTE POR CONFIRMAR | O14: 🟢 FUNCIONAL | P14: =M14-B14 -> 0 | Q14: 46084 | R14: =IF(Q14-B14<0,NOW()-B14,Q14-B14) -> 0 | S14: NO | T14: N/A | U14: =IF(R14=GENERALIDADES!$I$1,#REF!,"0") -> 0 | V14: NO | W14: N/A | X14: =IF(U14=GENERALIDADES!$K$3,T14,"0") -> 0 | Y14: DESAJUSTE | Z14: NO | AC14: CERRADO | AD14: =M14-B14 -> 0 | AE14: =NETWORKDAYS(B14,Q14,) -> 1 | AF14: =IF(AND((NETWORKDAYS(B14,M14,)<=3),(NOT(ISBLANK(B14)))),TRUE(), FALSE()) -> TRUE
A15: 25721 | B15: 46084 | C15: CAMA ELÉCTRICA | D15: Dometal | E15: QUAXAR 131-70 | F15: 3706A45 | G15: 544643 | H15: HOSPITALIZACIÓN ADULTO 5° PISO | J15: cama paciente que no funciona los controles | K15: Se revisa equipo y se detecta daño en el control de mando del mismo, no permite reparación, por tal motivo se inicia proceso de adquisición de repuesto, a la espera de llegada e instalación. Soporte duplicado, repuesto solicitado. | L15: Victor Lopez | M15: 46084 | N15: ⚠ PTE POR CONFIRMAR | O15: 🟡 EN ESPERA DE REPUESTO | P15: =M15-B15 -> 0 | Q15: 46084 | R15: =IF(Q15-B15<0,NOW()-B15,Q15-B15) -> 0 | S15: NO | T15: N/A | U15: =IF(R15=GENERALIDADES!$I$1,#REF!,"0") -> 0 | V15: NO | W15: N/A | X15: =IF(U15=GENERALIDADES!$K$3,T15,"0") -> 0 | Y15: FALLA INTERNA | Z15: NO | AC15: PENDIENTE | AD15: =M15-B15 -> 0 | AE15: =NETWORKDAYS(B15,Q15,) -> 1 | AF15: =IF(AND((NETWORKDAYS(B15,M15,)<=3),(NOT(ISBLANK(B15)))),TRUE(), FALSE()) -> TRUE
A16: 25723 | B16: 46084 | C16: TENSIÓMETRO MANUAL | D16: Alpk2 | E16: NO DEFINIDO | F16: 136266 | G16: 548574 | H16: CONSULTA EXTERNA | J16: buenos días para solicitar revisar tensiómetro del consultorio 10, gracias quedo atenta. | K16: Se revisa el equipo y se encuentra pera en mal estado, se procede a reparar y se realizan pruebas funcionales, se entrega al servicio en buenas condiciones. | L16: Victor Lopez | M16: 46087 | N16: ⚠ PTE POR CONFIRMAR | O16: 🟢 FUNCIONAL | P16: =M16-B16 -> 3 | Q16: 46087 | R16: =IF(Q16-B16<0,NOW()-B16,Q16-B16) -> 3 | S16: NO | T16: N/A | U16: =IF(R16=GENERALIDADES!$I$1,#REF!,"0") -> 0 | V16: NO | W16: N/A | X16: =IF(U16=GENERALIDADES!$K$3,T16,"0") -> 0 | Y16: DESAJUSTE | Z16: NO | AC16: CERRADO | AD16: =M16-B16 -> 3 | AE16: =NETWORKDAYS(B16,Q16,) -> 4 | AF16: =IF(AND((NETWORKDAYS(B16,M16,)<=3),(NOT(ISBLANK(B16)))),TRUE(), FALSE()) -> FALSE
A17: 25724 | B17: 46084 | C17: MONITOR DE SIGNOS VITALES | D17: Edan | E17: IM70 | F17: 360080-M17C02250007 | G17: 550042 | H17: HOSPITALIZACIÓN GINECO-OBSTETRICIA | I17: Sala de Partos | J17: s se solicita revisar monito de signos vitales en sala de partos, no toma tension arterial, activo fijo #550042 | K17: Se revisa monitor y se encuentra daño en brazalete, se realiza cambio y se entrega uno nuevo al servicio, se realizan pruebas funcionales y se entrega al servicio el equipo en buenas condiciones. | L17: Victor Lopez | M17: 46084 | N17: ⚠ PTE POR CONFIRMAR | O17: 🟢 FUNCIONAL | P17: =M17-B17 -> 0 | Q17: 46084 | R17: =IF(Q17-B17<0,NOW()-B17,Q17-B17) -> 0 | S17: NO | T17: N/A | U17: =IF(R17=GENERALIDADES!$I$1,#REF!,"0") -> 0 | V17: NO | W17: N/A | X17: =IF(U17=GENERALIDADES!$K$3,T17,"0") -> 0 | Y17: FALLA INTERNA | Z17: SÍ | AA17: Se entrega brazalete nuevo adulto 1 vía | AC17: CERRADO | AD17: =M17-B17 -> 0 | AE17: =NETWORKDAYS(B17,Q17,) -> 1 | AF17: =IF(AND((NETWORKDAYS(B17,M17,)<=3),(NOT(ISBLANK(B17)))),TRUE(), FALSE()) -> TRUE
A18: 25727 | B18: 46084 | C18: MONITOR DE SIGNOS VITALES | D18: Edan | E18: M50 | F18: 333123-M14102120047-01 | G18: 545690 | H18: HOSPITALIZACIÓN QUIRÚRGICAS | J18: se solicita el favor de revisar oximetro del monitor de signos de la estacion #1 de quirurgicas, s ele revento el resorte de pinza, por lo que se encuentra sujeto con micropore, si funciona y censa la pulsioximetria. | K18: Se revisa el equipo y se encuentra daño en sensor de SPO2, se procede a reparar y se hacen pruebas funcionales, se retorna al servicio en buenas condiciones. | L18: Victor Lopez | M18: 46085 | N18: ⚠ PTE POR CONFIRMAR | O18: 🟢 FUNCIONAL | P18: =M18-B18 -> 1 | Q18: 46085 | R18: =IF(Q18-B18<0,NOW()-B18,Q18-B18) -> 1 | S18: NO | T18: N/A | U18: =IF(R18=GENERALIDADES!$I$1,#REF!,"0") -> 0 | V18: NO | W18: N/A | X18: =IF(U18=GENERALIDADES!$K$3,T18,"0") -> 0 | Y18: DESAJUSTE | Z18: NO | AC18: CERRADO | AD18: =M18-B18 -> 1 | AE18: =NETWORKDAYS(B18,Q18,) -> 2 | AF18: =IF(AND((NETWORKDAYS(B18,M18,)<=3),(NOT(ISBLANK(B18)))),TRUE(), FALSE()) -> TRUE
A19: 25732 | B19: 46084 | C19: MONITOR DE SIGNOS VITALES | D19: Mindray | E19: BENEVIEW T5 | F19: CM-3B134854 | G19: 545474 | H19: CUIDADO INTENSIVO ADULTO | J19: cubiculo 221 de uci adultos estacion 2, con termometro y saturador dañados. se deja termometro en cajon de estacion y saturador de oxigeno en cubiculo | K19: Se revisa el equipo y se encuentra daño en sensor de temperatura, se inicia proceso de adquisición, pendiente de entrega. 12/03/2026 se entrega sensor de temperatura nuevo al servicio y se hacen pruebas funcionales. Equipo Ok. | L19: Victor Lopez | M19: 46084 | N19: ⚠ PTE POR CONFIRMAR | O19: 🟢 FUNCIONAL | P19: =M19-B19 -> 0 | Q19: 46085 | R19: =IF(Q19-B19<0,NOW()-B19,Q19-B19) -> 1 | S19: NO | T19: N/A | U19: =IF(R19=GENERALIDADES!$I$1,#REF!,"0") -> 0 | V19: NO | W19: N/A | X19: =IF(U19=GENERALIDADES!$K$3,T19,"0") -> 0 | Y19: FALTA DE CONSUMIBLE | Z19: SÍ | AA19: Se entrega sensor de temperatura nuevo al servicio | AC19: CERRADO | AD19: =M19-B19 -> 0 | AE19: =NETWORKDAYS(B19,Q19,) -> 2 | AF19: =IF(AND((NETWORKDAYS(B19,M19,)<=3),(NOT(ISBLANK(B19)))),TRUE(), FALSE()) -> TRUE
A20: 25738 | B20: 46084 | C20: MONITOR DE SIGNOS VITALES | D20: N/A | E20: N/A | F20: N/A | G20: N/A | H20: QUIRÓFANO | J20: buenos dias por favor revisar sensor de oximetria monitor edan sala 4 gracias | K20: Se revisa equipo y se encuentra daño en conector del sensor al equipo, se procede a reparar el sensor y se realizan pruebas funcionales, se entrega al servicio en buenas condiciones. | L20: Victor Lopez | M20: 46084 | N20: ⚠ PTE POR CONFIRMAR | O20: 🟢 FUNCIONAL | P20: =M20-B20 -> 0 | Q20: 46084 | R20: =IF(Q20-B20<0,NOW()-B20,Q20-B20) -> 0 | S20: NO | T20: N/A | U20: =IF(R20=GENERALIDADES!$I$1,#REF!,"0") -> 0 | V20: NO | W20: N/A | X20: =IF(U20=GENERALIDADES!$K$3,T20,"0") -> 0 | Y20: DESAJUSTE | Z20: NO | AC20: CERRADO | AD20: =M20-B20 -> 0 | AE20: =NETWORKDAYS(B20,Q20,) -> 1 | AF20: =IF(AND((NETWORKDAYS(B20,M20,)<=3),(NOT(ISBLANK(B20)))),TRUE(), FALSE()) -> TRUE
A21: 25745 | B21: 46084 | C21: DESFIBRILADOR | D21: Comen | E21: S5 | F21: S5230703024 | G21: 572076 | H21: CUIDADO INTENSIVO ADULTO | J21: por favor revisar urgente carro de paro de la uci que presenta fallas en la realizacion de la prueba en el paso de la fuente de energia | K21: Se revisa equipo y se encuentra daño en palas de descarga, se procede a solicitar y se inicia proceso de adquisición. equipo fuera de servicio en taller de mantenimiento biomédico hasta entrega de repuesto. | L21: Camilo Ramirez | M21: 46090 | N21: ⚙ TRABAJANDO | O21: 🔴 FUERA DE SERVICIO | P21: =M21-B21 -> 6 | R21: =IF(Q21-B21<0,NOW()-B21,Q21-B21) -> 30.649708 | S21: SI | T21: PARCIAL | U21: =IF(R21=GENERALIDADES!$I$1,#REF!,"0") -> 0 | V21: NO | W21: N/A | X21: =IF(U21=GENERALIDADES!$K$3,T21,"0") -> 0 | Y21: FALLA INTERNA | Z21: NO | AC21: PENDIENTE COTIZAR | AD21: =M21-B21 -> 6 | AE21: =NETWORKDAYS(B21,Q21,) -> -32917 | AF21: =IF(AND((NETWORKDAYS(B21,M21,)<=3),(NOT(ISBLANK(B21)))),TRUE(), FALSE()) -> FALSE
A22: 25746 | B22: 46084 | C22: OTROS EQUIPOS BIOMÉDICOS | D22: N/A | E22: N/A | F22: N/A | G22: N/A | H22: BANCO DE SANGRE | J22: hola, buen dia, se solicita amablemente la colaboracion para cambiar y/o ajustar la posicion del agitador del plaquetas ya que se encuentra donde no corresponde. | K22: se realiza traslado del equipo a nuevo puesto y se hacen pruebas funcionales. Equipo Ok. | L22: Victor Lopez | M22: 46084 | N22: ⚠ PTE POR CONFIRMAR | O22: 🟢 FUNCIONAL | P22: =M22-B22 -> 0 | Q22: 46084 | R22: =IF(Q22-B22<0,NOW()-B22,Q22-B22) -> 0 | S22: NO | T22: N/A | U22: =IF(R22=GENERALIDADES!$I$1,#REF!,"0") -> 0 | V22: NO | W22: N/A | X22: =IF(U22=GENERALIDADES!$K$3,T22,"0") -> 0 | Y22: NO PRESENTA DAÑO | Z22: NO | AC22: CERRADO | AD22: =M22-B22 -> 0 | AE22: =NETWORKDAYS(B22,Q22,) -> 1 | AF22: =IF(AND((NETWORKDAYS(B22,M22,)<=3),(NOT(ISBLANK(B22)))),TRUE(), FALSE()) -> TRUE
A23: 25756 | B23: 46085 | C23: MONITOR DE SIGNOS VITALES | D23: Comen | E23: C80 | F23: K8231030005 | G23: 572055 | H23: URGENCIAS ADULTOS | I23: Reanimación | J23: se solicita el arreglo del brasalete del monitor de reanimacion que al insuflar se le siente fuga y no toma la presion. | K23: Se revisa el equipo y se encuentra fuga en brazalete, no permite reparación, se procede a realizar el cambio del brazalete y se entrega uno nuevo al servicio, se realizan pruebas funcionales, equipo ok. | L23: Victor Lopez | M23: 46085 | N23: ⚠ PTE POR CONFIRMAR | O23: 🟢 FUNCIONAL | P23: =M23-B23 -> 0 | Q23: 46085 | R23: =IF(Q23-B23<0,NOW()-B23,Q23-B23) -> 0 | S23: NO | T23: N/A | U23: =IF(R23=GENERALIDADES!$I$1,#REF!,"0") -> 0 | V23: NO | W23: N/A | X23: =IF(U23=GENERALIDADES!$K$3,T23,"0") -> 0 | Y23: DESGASTE | Z23: SÍ | AA23: Se entrega brazalete 1 vía adulto nuevo al servicio | AC23: CERRADO | AD23: =M23-B23 -> 0 | AE23: =NETWORKDAYS(B23,Q23,) -> 1 | AF23: =IF(AND((NETWORKDAYS(B23,M23,)<=3),(NOT(ISBLANK(B23)))),TRUE(), FALSE()) -> TRUE
A24: 25768 | B24: 46085 | C24: MONITOR DE SIGNOS VITALES | D24: Edan | E24: iM70 | F24: 360080-M20909270001 | G24: 573325 | H24: URGENCIAS ADULTOS | I24: Consultorio | J24: buen dia. por favor revisar saturador de o2 de monitor de signos vitales de consultorio de urgencias adultos, por favor urgente . muchas gracias. | K24: Se revisa el equipo y se encuentra daño en sensor de SPO2, se procede a reparar y se hacen pruebas funcionales, se retorna al servicio en buenas condiciones. | L24: Victor Lopez | M24: 46085 | N24: ⚠ PTE POR CONFIRMAR | O24: 🟢 FUNCIONAL | P24: =M24-B24 -> 0 | Q24: 46085 | R24: =IF(Q24-B24<0,NOW()-B24,Q24-B24) -> 0 | S24: NO | T24: N/A | U24: =IF(R24=GENERALIDADES!$I$1,#REF!,"0") -> 0 | V24: NO | W24: N/A | X24: =IF(U24=GENERALIDADES!$K$3,T24,"0") -> 0 | Y24: DESAJUSTE | Z24: NO | AC24: CERRADO | AD24: =M24-B24 -> 0 | AE24: =NETWORKDAYS(B24,Q24,) -> 1 | AF24: =IF(AND((NETWORKDAYS(B24,M24,)<=3),(NOT(ISBLANK(B24)))),TRUE(), FALSE()) -> TRUE
A25: 25770 | B25: 46085 | C25: CAMA ELÉCTRICA | D25: Los Pinos | E25: 1060 BC | F25: 502387 | G25: 545501 | H25: CUIDADO INTENSIVO ADULTO | J25: se solicita amablemente de manera prioritaria servicio de mantenimiento para cama ubicada en cubiculo ·# 27 de uci adulto ya que no enciende | K25: se revisa cama y se encuentra daño en paneles laterales, se inicia proceso de reparación, requiere reconstrucción de conexiones electrónicas internas del panel y revisión del módulo principal. en taller de mantenimiento biomédico a la espera de reparación. | L25: Victor Lopez | M25: 46085 | N25: ⚙ TRABAJANDO | O25: 🔴 FUERA DE SERVICIO | P25: =M25-B25 -> 0 | Q25: 46085 | R25: =IF(Q25-B25<0,NOW()-B25,Q25-B25) -> 0 | S25: NO | T25: N/A | U25: =IF(R25=GENERALIDADES!$I$1,#REF!,"0") -> 0 | V25: NO | W25: N/A | X25: =IF(U25=GENERALIDADES!$K$3,T25,"0") -> 0 | Y25: DESAJUSTE | Z25: NO | AC25: PENDIENTE | AD25: =M25-B25 -> 0 | AE25: =NETWORKDAYS(B25,Q25,) -> 1 | AF25: =IF(AND((NETWORKDAYS(B25,M25,)<=3),(NOT(ISBLANK(B25)))),TRUE(), FALSE()) -> TRUE
A26: 25783 | B26: 46085 | C26: VENTILADOR MECÁNICO | D26: N/A | E26: N/A | F26: N/A | G26: N/A | H26: CUIDADO INTENSIVO PEDIÁTRICO | J26: valvula draguer con mal funcionamiento( marca fuga) | K26: Se revisa válvula y se encuentra fuga en vaso de trampa de agua, se procede a realizar el cambio de la trampa y se hacen pruebas funcionales, equipo ok. | L26: Victor Lopez | M26: 46085 | N26: ⚠ PTE POR CONFIRMAR | O26: 🟢 FUNCIONAL | P26: =M26-B26 -> 0 | Q26: 46085 | R26: =IF(Q26-B26<0,NOW()-B26,Q26-B26) -> 0 | S26: NO | T26: N/A | U26: =IF(R26=GENERALIDADES!$I$1,#REF!,"0") -> 0 | V26: NO | W26: N/A | X26: =IF(U26=GENERALIDADES!$K$3,T26,"0") -> 0 | Y26: DESAJUSTE | Z26: NO | AC26: CERRADO | AD26: =M26-B26 -> 0 | AE26: =NETWORKDAYS(B26,Q26,) -> 1 | AF26: =IF(AND((NETWORKDAYS(B26,M26,)<=3),(NOT(ISBLANK(B26)))),TRUE(), FALSE()) -> TRUE
A27: 25785 | B27: 46085 | C27: VENTILADOR MECÁNICO | D27: Mindray | E27: SV-300 | F27: GR-98010197 | G27: 574284 | H27: URGENCIAS ADULTOS | I27: Reanimación | J27: pántalla de ventilador # 2 mindray bloqueado en sala de reanimacion urgencias adulto. de carácter urgente. | K27: Se revisa el equipo y se encuentra bloqueo en pantalla, se procede a desbloquear y se realizan pruebas funcionales, se entrega al servicio en buenas condiciones. | L27: Victor Lopez | M27: 46085 | N27: ⚠ PTE POR CONFIRMAR | O27: 🟢 FUNCIONAL | P27: =M27-B27 -> 0 | Q27: 46085 | R27: =IF(Q27-B27<0,NOW()-B27,Q27-B27) -> 0 | S27: NO | T27: N/A | U27: =IF(R27=GENERALIDADES!$I$1,#REF!,"0") -> 0 | V27: NO | W27: N/A | X27: =IF(U27=GENERALIDADES!$K$3,T27,"0") -> 0 | Y27: USO INADECUADO | Z27: NO | AC27: CERRADO | AD27: =M27-B27 -> 0 | AE27: =NETWORKDAYS(B27,Q27,) -> 1 | AF27: =IF(AND((NETWORKDAYS(B27,M27,)<=3),(NOT(ISBLANK(B27)))),TRUE(), FALSE()) -> TRUE
A28: 25789 | B28: 46085 | C28: FLUJÓMETRO | D28: N/A | E28: N/A | F28: N/A | G28: N/A | H28: QUIRÓFANO | J28: buenas tardes, se realiza soporte de flujometro descalibrado | K28: Se revisa equipo y se encuentra dentro de los parámetros normales de funcionamiento, se realiza chequeo de fugas, equipo ok. | L28: Victor Lopez | M28: 46085 | N28: ⚠ PTE POR CONFIRMAR | O28: 🟢 FUNCIONAL | P28: =M28-B28 -> 0 | Q28: 46085 | R28: =IF(Q28-B28<0,NOW()-B28,Q28-B28) -> 0 | S28: NO | T28: N/A | U28: =IF(R28=GENERALIDADES!$I$1,#REF!,"0") -> 0 | V28: NO | W28: N/A | X28: =IF(U28=GENERALIDADES!$K$3,T28,"0") -> 0 | Y28: NO PRESENTA DAÑO | Z28: NO | AC28: CERRADO | AD28: =M28-B28 -> 0 | AE28: =NETWORKDAYS(B28,Q28,) -> 1 | AF28: =IF(AND((NETWORKDAYS(B28,M28,)<=3),(NOT(ISBLANK(B28)))),TRUE(), FALSE()) -> TRUE
A29: 25795 | B29: 46085 | C29: MONITOR DE SIGNOS VITALES | D29: Edan | E29: M50 | F29: 333123-M14102120024-01 | G29: 545692 | H29: HOSPITALIZACIÓN QUIRÚRGICAS | J29: buenas tardes favor revisar el oximetro del monitor af545692 | K29: Se revisa el equipo y se encuentra daño en sensor de SPO2, no permite reparación, se procede a realizar cambio de sensor, se realizan pruebas funcionales y se entrega al servicio en buenas condiciones. | L29: Victor Lopez | M29: 46085 | N29: ⚠ PTE POR CONFIRMAR | O29: 🟢 FUNCIONAL | P29: =M29-B29 -> 0 | Q29: 46085 | R29: =IF(Q29-B29<0,NOW()-B29,Q29-B29) -> 0 | S29: NO | T29: N/A | U29: =IF(R29=GENERALIDADES!$I$1,#REF!,"0") -> 0 | V29: NO | W29: N/A | X29: =IF(U29=GENERALIDADES!$K$3,T29,"0") -> 0 | Y29: FALLA INTERNA | Z29: SÍ | AA29: Se entrega sensor de SPO2 nuevo al servicio SN:FD202510280920413 | AC29: CERRADO | AD29: =M29-B29 -> 0 | AE29: =NETWORKDAYS(B29,Q29,) -> 1 | AF29: =IF(AND((NETWORKDAYS(B29,M29,)<=3),(NOT(ISBLANK(B29)))),TRUE(), FALSE()) -> TRUE
A30: 25800 | B30: 46086 | C30: OTROS EQUIPOS BIOMÉDICOS | D30: N/A | E30: N/A | F30: N/A | G30: N/A | H30: URGENCIAS ADULTOS | J30: buenos dias, en el servicio de obs hombres no deja registrar oxigenos, muchas gracisa | K30: Se revisa equipo y se encuentra en buenas condiciones funcionales. | L30: Victor Lopez | M30: 46086 | N30: ⚠ PTE POR CONFIRMAR | O30: 🟢 FUNCIONAL | P30: =M30-B30 -> 0 | Q30: 46086 | R30: =IF(Q30-B30<0,NOW()-B30,Q30-B30) -> 0 | S30: NO | T30: N/A | U30: =IF(R30=GENERALIDADES!$I$1,#REF!,"0") -> 0 | V30: NO | W30: N/A | X30: =IF(U30=GENERALIDADES!$K$3,T30,"0") -> 0 | Y30: NO PRESENTA DAÑO | Z30: NO | AC30: CERRADO | AD30: =M30-B30 -> 0 | AE30: =NETWORKDAYS(B30,Q30,) -> 1 | AF30: =IF(AND((NETWORKDAYS(B30,M30,)<=3),(NOT(ISBLANK(B30)))),TRUE(), FALSE()) -> TRUE
A31: 25829 | B31: 46086 | C31: FONENDOSCOPIO | D31: Adc | E31: ADSCOPE-LITE REF:609BK | F31: NA | G31: 573479 | H31: CUIDADO INTENSIVO PEDIÁTRICO | J31: buena tar de se solicita el favor de arreglar la oliva del fonendoscopio del cubiculo 3 de la uci pediatrica muchas gracias | K31: Se revisa equipo y se encuentra daño en oliva, se procede a realizar el cambio y se hacen pruebas funcionales, se retorna al servicio en buenas condiciones. | L31: Victor Lopez | M31: 46086 | N31: ⚠ PTE POR CONFIRMAR | O31: 🟢 FUNCIONAL | P31: =M31-B31 -> 0 | Q31: 46086 | R31: =IF(Q31-B31<0,NOW()-B31,Q31-B31) -> 0 | S31: NO | T31: N/A | U31: =IF(R31=GENERALIDADES!$I$1,#REF!,"0") -> 0 | V31: NO | W31: N/A | X31: =IF(U31=GENERALIDADES!$K$3,T31,"0") -> 0 | Y31: DESGASTE | Z31: NO | AC31: CERRADO | AD31: =M31-B31 -> 0 | AE31: =NETWORKDAYS(B31,Q31,) -> 1 | AF31: =IF(AND((NETWORKDAYS(B31,M31,)<=3),(NOT(ISBLANK(B31)))),TRUE(), FALSE()) -> TRUE
A32: 25839 | B32: 46086 | C32: MONITOR DE SIGNOS VITALES | D32: Draeger | E32: VISTA 120 S | F32: S2SNF4421 | G32: 573314 | H32: CUIDADO INTENSIVO NEONATAL | J32: favor revisar sensor de temperatura del monitor de la temperatura de la cama n.6 uci neonatos | K32: Se revisa equipo y se encuentra sensor de temperatura en mal estao, se procede a cambiar y se realizan pruebas funcionales. Equipo ok. | L32: Victor Lopez | M32: 46086 | N32: ⚠ PTE POR CONFIRMAR | O32: 🟢 FUNCIONAL | P32: =M32-B32 -> 0 | Q32: 46086 | R32: =IF(Q32-B32<0,NOW()-B32,Q32-B32) -> 0 | S32: NO | T32: N/A | U32: =IF(R32=GENERALIDADES!$I$1,#REF!,"0") -> 0 | V32: NO | W32: N/A | X32: =IF(U32=GENERALIDADES!$K$3,T32,"0") -> 0 | Y32: DESGASTE | Z32: NO | AC32: CERRADO | AD32: =M32-B32 -> 0 | AE32: =NETWORKDAYS(B32,Q32,) -> 1 | AF32: =IF(AND((NETWORKDAYS(B32,M32,)<=3),(NOT(ISBLANK(B32)))),TRUE(), FALSE()) -> TRUE
A33: 25845 | B33: 46087 | C33: MONITOR DE SIGNOS VITALES | G33: 572058 | H33: URGENCIAS ADULTOS | J33: buenos dias solicito soporte tecnico para el saturador del monitor de signos vitales de expansion hombres, muchas gracias | K33: =LOWER(Marzo_2026[[#This Row],[DESCRIPCIÓN DE DAÑO]]) -> buenos dias solicito soporte tecnico para el saturador del monitor de signos vitales de expansion hombres, muchas gracias | N33: ⚠ PTE POR CONFIRMAR | P33: =M33-B33 -> -46087 | R33: =IF(Q33-B33<0,NOW()-B33,Q33-B33) -> 27.649708 | U33: =IF(R33=GENERALIDADES!$I$1,#REF!,"0") -> 0 | X33: =IF(U33=GENERALIDADES!$K$3,T33,"0") -> 0 | AD33: =M33-B33 -> -46087 | AE33: =NETWORKDAYS(B33,Q33,) -> -32920 | AF33: =IF(AND((NETWORKDAYS(B33,M33,)<=3),(NOT(ISBLANK(B33)))),TRUE(), FALSE()) -> TRUE
A34: 25846 | B34: 46087 | C34: TERMOHIGRÓMETRO | D34: N/A | E34: N/A | F34: N/A | G34: N/A | H34: URGENCIAS ADULTOS | J34: buenos dias solicito soporte tecnico para el termometro de expansion hombres ya que no prende, muchas gracias | K34: Se revisa el equipo y se encuentra en buenas condiciones funcionales, se verifica estado de las baterías y el display, equipo ok. | L34: Leonardo Marín | M34: 46087 | N34: ⚠ PTE POR CONFIRMAR | O34: 🟢 FUNCIONAL | P34: =M34-B34 -> 0 | Q34: 46087 | R34: =IF(Q34-B34<0,NOW()-B34,Q34-B34) -> 0 | S34: NO | T34: N/A | U34: =IF(R34=GENERALIDADES!$I$1,#REF!,"0") -> 0 | V34: NO | W34: N/A | X34: =IF(U34=GENERALIDADES!$K$3,T34,"0") -> 0 | Y34: NO PRESENTA DAÑO | Z34: NO | AC34: CERRADO | AD34: =M34-B34 -> 0 | AE34: =NETWORKDAYS(B34,Q34,) -> 1 | AF34: =IF(AND((NETWORKDAYS(B34,M34,)<=3),(NOT(ISBLANK(B34)))),TRUE(), FALSE()) -> TRUE
A35: 25855 | B35: 46087 | C35: TENSIÓMETRO MANUAL | D35: Alpk2 | E35: NO DEFINIDO | F35: 136266 | G35: 548574 | H35: CONSULTA EXTERNA | J35: se solicita revisar tensiometro manual del consultorio 10 ya que se observa dañado consulta externa segundo piso de manera ugenteeee ya que se estamos en consulta muchas gracias | K35: Se revisa el equipo y se encuentra pera en mal estado, se procede a reparar y se realizan pruebas funcionales, se entrega al servicio en buenas condiciones. | L35: Victor Lopez | M35: 46087 | N35: ⚠ PTE POR CONFIRMAR | O35: 🟢 FUNCIONAL | P35: =M35-B35 -> 0 | Q35: 46087 | R35: =IF(Q35-B35<0,NOW()-B35,Q35-B35) -> 0 | S35: NO | T35: N/A | U35: =IF(R35=GENERALIDADES!$I$1,#REF!,"0") -> 0 | V35: NO | W35: N/A | X35: =IF(U35=GENERALIDADES!$K$3,T35,"0") -> 0 | Y35: DESAJUSTE | Z35: NO | AC35: CERRADO | AD35: =M35-B35 -> 0 | AE35: =NETWORKDAYS(B35,Q35,) -> 1 | AF35: =IF(AND((NETWORKDAYS(B35,M35,)<=3),(NOT(ISBLANK(B35)))),TRUE(), FALSE()) -> TRUE
A36: 25856 | B36: 46087 | C36: CAMA ELÉCTRICA | D36: Los Pinos | E36: 1060 BC | F36: 502383 | G36: 545499 | H36: CUIDADO INTENSIVO ADULTO | J36: buenos dias se reporta cama del cubiculo 15 no permite subir la cabecera. | K36: Se revisa cama y se encuentra daño en motor de cabecera, se procede a realizar el cambio del motor y se hacen pruebas funcionales, se entrega al servicio en buenas condiciones. | L36: Victor Lopez | M36: 46087 | N36: ⚠ PTE POR CONFIRMAR | O36: 🟢 FUNCIONAL | P36: =M36-B36 -> 0 | Q36: 46087 | R36: =IF(Q36-B36<0,NOW()-B36,Q36-B36) -> 0 | S36: NO | T36: N/A | U36: =IF(R36=GENERALIDADES!$I$1,#REF!,"0") -> 0 | V36: NO | W36: N/A | X36: =IF(U36=GENERALIDADES!$K$3,T36,"0") -> 0 | Y36: DESAJUSTE | Z36: NO | AC36: CERRADO | AD36: =M36-B36 -> 0 | AE36: =NETWORKDAYS(B36,Q36,) -> 1 | AF36: =IF(AND((NETWORKDAYS(B36,M36,)<=3),(NOT(ISBLANK(B36)))),TRUE(), FALSE()) -> TRUE
A37: 25861 | B37: 46087 | C37: MONITOR DE SIGNOS VITALES | D37: Edan | E37: M50 | F37: 333123-M14102120001 | G37: 545697 | H37: HOSPITALIZACIÓN ADULTO 4° PISO | J37: por favor cambiar brazalete de monitor de signos de activo fijo 545697 presenta fuga | K37: Se revisa equipo y se encuentra fuga en brazalete, no permite reparación, se procede a realizar el cambio y se entrega uno nuevo al servicio, se realizan pruebas funcionales. Equipo -ok | L37: Victor Lopez | M37: 46087 | N37: ⚠ PTE POR CONFIRMAR | O37: 🟢 FUNCIONAL | P37: =M37-B37 -> 0 | Q37: 46087 | R37: =IF(Q37-B37<0,NOW()-B37,Q37-B37) -> 0 | S37: NO | T37: N/A | U37: =IF(R37=GENERALIDADES!$I$1,#REF!,"0") -> 0 | V37: NO | W37: N/A | X37: =IF(U37=GENERALIDADES!$K$3,T37,"0") -> 0 | Y37: DESGASTE | Z37: SÍ | AA37: Se entrega brazalete 1 vía adulto nuevo al servicio | AC37: CERRADO | AD37: =M37-B37 -> 0 | AE37: =NETWORKDAYS(B37,Q37,) -> 1 | AF37: =IF(AND((NETWORKDAYS(B37,M37,)<=3),(NOT(ISBLANK(B37)))),TRUE(), FALSE()) -> TRUE
A38: 25863 | B38: 46087 | C38: MONITOR DE SIGNOS VITALES | D38: Edan | E38: iM70 | F38: 360080-M20909270003 | G38: 573330 | H38: HOSPITALIZACIÓN GINECO-OBSTETRICIA | I38: Sala de Partos | J38: buenos dias se monta soporte para pulso oximetro sala de partos con activo fijo 573330 | K38: Se revisa equipo y se encuentra daño en sensor de SPO2, no permite reparación, se procede a realizar el cambio y se entrega uno nuevo al servicio, se realizan pruebas funcionales. Equipo -ok | L38: Victor Lopez | M38: 46087 | N38: ⚠ PTE POR CONFIRMAR | O38: 🟢 FUNCIONAL | P38: =M38-B38 -> 0 | Q38: 46087 | R38: =IF(Q38-B38<0,NOW()-B38,Q38-B38) -> 0 | S38: NO | T38: N/A | U38: =IF(R38=GENERALIDADES!$I$1,#REF!,"0") -> 0 | V38: NO | W38: N/A | X38: =IF(U38=GENERALIDADES!$K$3,T38,"0") -> 0 | Y38: DESGASTE | Z38: SÍ | AA38: Se realiza entrega de sensor de SPO2 adulto nuevo al servicio con serie: FD202510280920416 | AC38: CERRADO | AD38: =M38-B38 -> 0 | AE38: =NETWORKDAYS(B38,Q38,) -> 1 | AF38: =IF(AND((NETWORKDAYS(B38,M38,)<=3),(NOT(ISBLANK(B38)))),TRUE(), FALSE()) -> TRUE
A39: 25865 | B39: 46087 | C39: MONITOR DE SIGNOS VITALES | D39: Edan | E39: M50 | F39: 333123-M13707020049-01 | G39: 545372 | H39: HOSPITALIZACIÓN ADULTO 4° PISO | J39: buenos días, se realiza revisión del monitor de signos vitales, efectuando el cambio del brazalete por uno nuevo con el código 24537. | K39: Se revisa equipo y se encuentra fuga en brazalete, no permite reparación, se procede a realizar el cambio y se entrega uno nuevo al servicio, se realizan pruebas funcionales. Equipo -ok | L39: Victor Lopez | M39: 46087 | N39: ⚠ PTE POR CONFIRMAR | O39: 🟢 FUNCIONAL | P39: =M39-B39 -> 0 | Q39: 46087 | R39: =IF(Q39-B39<0,NOW()-B39,Q39-B39) -> 0 | S39: NO | T39: N/A | U39: =IF(R39=GENERALIDADES!$I$1,#REF!,"0") -> 0 | V39: NO | W39: N/A | X39: =IF(U39=GENERALIDADES!$K$3,T39,"0") -> 0 | Y39: DESGASTE | Z39: SÍ | AA39: Se entrega brazalete 1 vía adulto nuevo al servicio | AC39: CERRADO | AD39: =M39-B39 -> 0 | AE39: =NETWORKDAYS(B39,Q39,) -> 1 | AF39: =IF(AND((NETWORKDAYS(B39,M39,)<=3),(NOT(ISBLANK(B39)))),TRUE(), FALSE()) -> TRUE
A40: 25867 | B40: 46087 | C40: MONITOR DE SIGNOS VITALES | D40: Edan | E40: M50 | F40: 333123-M13707020064-01 | G40: 545367 | H40: HOSPITALIZACIÓN ADULTO 5° PISO | J40: buenos dias, se solicita el favor de arreglo de oximetro de la estacion 2 del 5to piso, no funciona. | K40: Se revisa equipo y se encuentra daño en sensor de SPO2, no permite reparación, se procede a realizar el cambio del sensor y se entrega uno nuevo al servicio, se realizan pruebas funcionales. Equipo Ok | L40: Victor Lopez | M40: 46087 | N40: ⚠ PTE POR CONFIRMAR | O40: 🟢 FUNCIONAL | P40: =M40-B40 -> 0 | Q40: 46087 | R40: =IF(Q40-B40<0,NOW()-B40,Q40-B40) -> 0 | S40: NO | T40: N/A | U40: =IF(R40=GENERALIDADES!$I$1,#REF!,"0") -> 0 | V40: NO | W40: N/A | X40: =IF(U40=GENERALIDADES!$K$3,T40,"0") -> 0 | Y40: DESGASTE | Z40: SÍ | AA40: Se realiza entrega de sensor de SPO2 adulto nuevo al servicio con serie: FD202510280920499 | AC40: CERRADO | AD40: =M40-B40 -> 0 | AE40: =NETWORKDAYS(B40,Q40,) -> 1 | AF40: =IF(AND((NETWORKDAYS(B40,M40,)<=3),(NOT(ISBLANK(B40)))),TRUE(), FALSE()) -> TRUE
...
